2021-03-02 02:52:17,927 ERROR: Exception on /news/wp-includes/wlwmanifest.xml [GET] [in /home/alexluttrell2013/microblog/venv/lib/python3.8/site-packages/flask/app.py:1891]
Traceback (most recent call last):
  File "/home/alexluttrell2013/microblog/venv/lib/python3.8/site-packages/flask/app.py", line 2447, in wsgi_app
  File "/home/alexluttrell2013/microblog/venv/lib/python3.8/site-packages/flask/app.py", line 1952, in full_dispatch_request
  File "/home/alexluttrell2013/microblog/venv/lib/python3.8/site-packages/flask/app.py", line 1821, in handle_user_exception
  File "/home/alexluttrell2013/microblog/venv/lib/python3.8/site-packages/flask/_compat.py", line 39, in reraise
  File "/home/alexluttrell2013/microblog/venv/lib/python3.8/site-packages/flask/app.py", line 1948, in full_dispatch_request
  File "/home/alexluttrell2013/microblog/venv/lib/python3.8/site-packages/flask/app.py", line 2242, in preprocess_request
  File "/home/alexluttrell2013/microblog/app/main/routes.py", line 21, in before_request
    g.locale = str(get_locale())
  File "/home/alexluttrell2013/microblog/venv/lib/python3.8/site-packages/flask_babel/__init__.py", line 230, in get_locale
  File "/home/alexluttrell2013/microblog/venv/lib/python3.8/site-packages/babel/core.py", line 288, in parse
  File "/home/alexluttrell2013/microblog/venv/lib/python3.8/site-packages/babel/core.py", line 273, in _try_load
  File "/home/alexluttrell2013/microblog/venv/lib/python3.8/site-packages/babel/core.py", line 167, in __init__
  File "/home/alexluttrell2013/microblog/venv/lib/python3.8/site-packages/babel/localedata.py", line 64, in exists
  File "/home/alexluttrell2013/microblog/venv/lib/python3.8/site-packages/babel/localedata.py", line 47, in normalize_locale
  File "/home/alexluttrell2013/microblog/venv/lib/python3.8/site-packages/babel/localedata.py", line 76, in locale_identifiers
FileNotFoundError: [Errno 2] No such file or directory: '/home/alexluttrell2013/microblog/venv/lib/python3.8/site-packages/babel/locale-data'
2021-03-02 02:52:18,463 ERROR: Exception on /2018/wp-includes/wlwmanifest.xml [GET] [in /home/alexluttrell2013/microblog/venv/lib/python3.8/site-packages/flask/app.py:1891]
Traceback (most recent call last):
  File "/home/alexluttrell2013/microblog/venv/lib/python3.8/site-packages/flask/app.py", line 2447, in wsgi_app
  File "/home/alexluttrell2013/microblog/venv/lib/python3.8/site-packages/flask/app.py", line 1952, in full_dispatch_request
  File "/home/alexluttrell2013/microblog/venv/lib/python3.8/site-packages/flask/app.py", line 1821, in handle_user_exception
  File "/home/alexluttrell2013/microblog/venv/lib/python3.8/site-packages/flask/_compat.py", line 39, in reraise
  File "/home/alexluttrell2013/microblog/venv/lib/python3.8/site-packages/flask/app.py", line 1948, in full_dispatch_request
  File "/home/alexluttrell2013/microblog/venv/lib/python3.8/site-packages/flask/app.py", line 2242, in preprocess_request
  File "/home/alexluttrell2013/microblog/app/main/routes.py", line 21, in before_request
    g.locale = str(get_locale())
  File "/home/alexluttrell2013/microblog/venv/lib/python3.8/site-packages/flask_babel/__init__.py", line 230, in get_locale
  File "/home/alexluttrell2013/microblog/venv/lib/python3.8/site-packages/babel/core.py", line 288, in parse
  File "/home/alexluttrell2013/microblog/venv/lib/python3.8/site-packages/babel/core.py", line 273, in _try_load
  File "/home/alexluttrell2013/microblog/venv/lib/python3.8/site-packages/babel/core.py", line 167, in __init__
  File "/home/alexluttrell2013/microblog/venv/lib/python3.8/site-packages/babel/localedata.py", line 64, in exists
  File "/home/alexluttrell2013/microblog/venv/lib/python3.8/site-packages/babel/localedata.py", line 47, in normalize_locale
  File "/home/alexluttrell2013/microblog/venv/lib/python3.8/site-packages/babel/localedata.py", line 76, in locale_identifiers
FileNotFoundError: [Errno 2] No such file or directory: '/home/alexluttrell2013/microblog/venv/lib/python3.8/site-packages/babel/locale-data'
2021-03-02 02:52:18,830 ERROR: Exception on /2019/wp-includes/wlwmanifest.xml [GET] [in /home/alexluttrell2013/microblog/venv/lib/python3.8/site-packages/flask/app.py:1891]
Traceback (most recent call last):
  File "/home/alexluttrell2013/microblog/venv/lib/python3.8/site-packages/flask/app.py", line 2447, in wsgi_app
  File "/home/alexluttrell2013/microblog/venv/lib/python3.8/site-packages/flask/app.py", line 1952, in full_dispatch_request
  File "/home/alexluttrell2013/microblog/venv/lib/python3.8/site-packages/flask/app.py", line 1821, in handle_user_exception
  File "/home/alexluttrell2013/microblog/venv/lib/python3.8/site-packages/flask/_compat.py", line 39, in reraise
  File "/home/alexluttrell2013/microblog/venv/lib/python3.8/site-packages/flask/app.py", line 1948, in full_dispatch_request
  File "/home/alexluttrell2013/microblog/venv/lib/python3.8/site-packages/flask/app.py", line 2242, in preprocess_request
  File "/home/alexluttrell2013/microblog/app/main/routes.py", line 21, in before_request
    g.locale = str(get_locale())
  File "/home/alexluttrell2013/microblog/venv/lib/python3.8/site-packages/flask_babel/__init__.py", line 230, in get_locale
  File "/home/alexluttrell2013/microblog/venv/lib/python3.8/site-packages/babel/core.py", line 288, in parse
  File "/home/alexluttrell2013/microblog/venv/lib/python3.8/site-packages/babel/core.py", line 273, in _try_load
  File "/home/alexluttrell2013/microblog/venv/lib/python3.8/site-packages/babel/core.py", line 167, in __init__
  File "/home/alexluttrell2013/microblog/venv/lib/python3.8/site-packages/babel/localedata.py", line 64, in exists
  File "/home/alexluttrell2013/microblog/venv/lib/python3.8/site-packages/babel/localedata.py", line 47, in normalize_locale
  File "/home/alexluttrell2013/microblog/venv/lib/python3.8/site-packages/babel/localedata.py", line 76, in locale_identifiers
FileNotFoundError: [Errno 2] No such file or directory: '/home/alexluttrell2013/microblog/venv/lib/python3.8/site-packages/babel/locale-data'
2021-03-02 21:58:19,084 INFO: Microblog startup [in /home/alexluttrell2013/microblog/app/__init__.py:89]
2021-03-02 22:03:34,663 INFO: Microblog startup [in /home/alexluttrell2013/microblog/app/__init__.py:89]
2021-03-02 22:10:32,414 INFO: Microblog startup [in /home/alexluttrell2013/microblog/app/__init__.py:89]
2021-03-02 22:10:55,353 INFO: Microblog startup [in /home/alexluttrell2013/microblog/app/__init__.py:89]
2021-03-02 22:11:33,519 INFO: Microblog startup [in /home/alexluttrell2013/microblog/app/__init__.py:89]
2021-03-02 22:11:33,681 INFO: Microblog startup [in /home/alexluttrell2013/microblog/app/__init__.py:89]
2021-03-02 22:11:33,731 INFO: Microblog startup [in /home/alexluttrell2013/microblog/app/__init__.py:89]
2021-03-02 22:11:33,755 INFO: Microblog startup [in /home/alexluttrell2013/microblog/app/__init__.py:89]
2021-03-02 22:45:42,211 INFO: Microblog startup [in /home/alexluttrell2013/microblog/app/__init__.py:89]
2021-03-02 22:45:56,843 INFO: Microblog startup [in /home/alexluttrell2013/microblog/app/__init__.py:89]
2021-03-02 22:46:14,310 INFO: Microblog startup [in /home/alexluttrell2013/microblog/app/__init__.py:89]
2021-03-02 22:46:33,049 INFO: Microblog startup [in /home/alexluttrell2013/microblog/app/__init__.py:89]
2021-03-02 22:46:44,002 INFO: Microblog startup [in /home/alexluttrell2013/microblog/app/__init__.py:89]
2021-03-02 22:53:30,521 INFO: Microblog startup [in /home/alexluttrell2013/microblog/app/__init__.py:89]
2021-03-02 22:53:30,748 INFO: Microblog startup [in /home/alexluttrell2013/microblog/app/__init__.py:89]
2021-03-02 22:53:30,759 INFO: Microblog startup [in /home/alexluttrell2013/microblog/app/__init__.py:89]
2021-03-02 22:53:30,773 INFO: Microblog startup [in /home/alexluttrell2013/microblog/app/__init__.py:89]
