2021-03-02 02:09:49,925 ERROR: Exception on /website/wp-includes/wlwmanifest.xml [GET] [in /home/alexluttrell2013/microblog/venv/lib/python3.8/site-packages/flask/app.py:1891]
Traceback (most recent call last):
  File "/home/alexluttrell2013/microblog/venv/lib/python3.8/site-packages/flask/app.py", line 2447, in wsgi_app
  File "/home/alexluttrell2013/microblog/venv/lib/python3.8/site-packages/flask/app.py", line 1952, in full_dispatch_request
  File "/home/alexluttrell2013/microblog/venv/lib/python3.8/site-packages/flask/app.py", line 1821, in handle_user_exception
  File "/home/alexluttrell2013/microblog/venv/lib/python3.8/site-packages/flask/_compat.py", line 39, in reraise
  File "/home/alexluttrell2013/microblog/venv/lib/python3.8/site-packages/flask/app.py", line 1948, in full_dispatch_request
  File "/home/alexluttrell2013/microblog/venv/lib/python3.8/site-packages/flask/app.py", line 2242, in preprocess_request
  File "/home/alexluttrell2013/microblog/app/main/routes.py", line 21, in before_request
    g.locale = str(get_locale())
  File "/home/alexluttrell2013/microblog/venv/lib/python3.8/site-packages/flask_babel/__init__.py", line 230, in get_locale
  File "/home/alexluttrell2013/microblog/venv/lib/python3.8/site-packages/babel/core.py", line 288, in parse
  File "/home/alexluttrell2013/microblog/venv/lib/python3.8/site-packages/babel/core.py", line 273, in _try_load
  File "/home/alexluttrell2013/microblog/venv/lib/python3.8/site-packages/babel/core.py", line 167, in __init__
  File "/home/alexluttrell2013/microblog/venv/lib/python3.8/site-packages/babel/localedata.py", line 64, in exists
  File "/home/alexluttrell2013/microblog/venv/lib/python3.8/site-packages/babel/localedata.py", line 47, in normalize_locale
  File "/home/alexluttrell2013/microblog/venv/lib/python3.8/site-packages/babel/localedata.py", line 76, in locale_identifiers
FileNotFoundError: [Errno 2] No such file or directory: '/home/alexluttrell2013/microblog/venv/lib/python3.8/site-packages/babel/locale-data'
2021-03-02 02:09:50,138 ERROR: Exception on /wp/wp-includes/wlwmanifest.xml [GET] [in /home/alexluttrell2013/microblog/venv/lib/python3.8/site-packages/flask/app.py:1891]
Traceback (most recent call last):
  File "/home/alexluttrell2013/microblog/venv/lib/python3.8/site-packages/flask/app.py", line 2447, in wsgi_app
  File "/home/alexluttrell2013/microblog/venv/lib/python3.8/site-packages/flask/app.py", line 1952, in full_dispatch_request
  File "/home/alexluttrell2013/microblog/venv/lib/python3.8/site-packages/flask/app.py", line 1821, in handle_user_exception
  File "/home/alexluttrell2013/microblog/venv/lib/python3.8/site-packages/flask/_compat.py", line 39, in reraise
  File "/home/alexluttrell2013/microblog/venv/lib/python3.8/site-packages/flask/app.py", line 1948, in full_dispatch_request
  File "/home/alexluttrell2013/microblog/venv/lib/python3.8/site-packages/flask/app.py", line 2242, in preprocess_request
  File "/home/alexluttrell2013/microblog/app/main/routes.py", line 21, in before_request
    g.locale = str(get_locale())
  File "/home/alexluttrell2013/microblog/venv/lib/python3.8/site-packages/flask_babel/__init__.py", line 230, in get_locale
  File "/home/alexluttrell2013/microblog/venv/lib/python3.8/site-packages/babel/core.py", line 288, in parse
  File "/home/alexluttrell2013/microblog/venv/lib/python3.8/site-packages/babel/core.py", line 273, in _try_load
  File "/home/alexluttrell2013/microblog/venv/lib/python3.8/site-packages/babel/core.py", line 167, in __init__
  File "/home/alexluttrell2013/microblog/venv/lib/python3.8/site-packages/babel/localedata.py", line 64, in exists
  File "/home/alexluttrell2013/microblog/venv/lib/python3.8/site-packages/babel/localedata.py", line 47, in normalize_locale
  File "/home/alexluttrell2013/microblog/venv/lib/python3.8/site-packages/babel/localedata.py", line 76, in locale_identifiers
FileNotFoundError: [Errno 2] No such file or directory: '/home/alexluttrell2013/microblog/venv/lib/python3.8/site-packages/babel/locale-data'
2021-03-02 02:09:50,344 ERROR: Exception on /news/wp-includes/wlwmanifest.xml [GET] [in /home/alexluttrell2013/microblog/venv/lib/python3.8/site-packages/flask/app.py:1891]
Traceback (most recent call last):
  File "/home/alexluttrell2013/microblog/venv/lib/python3.8/site-packages/flask/app.py", line 2447, in wsgi_app
  File "/home/alexluttrell2013/microblog/venv/lib/python3.8/site-packages/flask/app.py", line 1952, in full_dispatch_request
  File "/home/alexluttrell2013/microblog/venv/lib/python3.8/site-packages/flask/app.py", line 1821, in handle_user_exception
  File "/home/alexluttrell2013/microblog/venv/lib/python3.8/site-packages/flask/_compat.py", line 39, in reraise
  File "/home/alexluttrell2013/microblog/venv/lib/python3.8/site-packages/flask/app.py", line 1948, in full_dispatch_request
  File "/home/alexluttrell2013/microblog/venv/lib/python3.8/site-packages/flask/app.py", line 2242, in preprocess_request
  File "/home/alexluttrell2013/microblog/app/main/routes.py", line 21, in before_request
    g.locale = str(get_locale())
  File "/home/alexluttrell2013/microblog/venv/lib/python3.8/site-packages/flask_babel/__init__.py", line 230, in get_locale
  File "/home/alexluttrell2013/microblog/venv/lib/python3.8/site-packages/babel/core.py", line 288, in parse
  File "/home/alexluttrell2013/microblog/venv/lib/python3.8/site-packages/babel/core.py", line 273, in _try_load
  File "/home/alexluttrell2013/microblog/venv/lib/python3.8/site-packages/babel/core.py", line 167, in __init__
  File "/home/alexluttrell2013/microblog/venv/lib/python3.8/site-packages/babel/localedata.py", line 64, in exists
  File "/home/alexluttrell2013/microblog/venv/lib/python3.8/site-packages/babel/localedata.py", line 47, in normalize_locale
  File "/home/alexluttrell2013/microblog/venv/lib/python3.8/site-packages/babel/localedata.py", line 76, in locale_identifiers
FileNotFoundError: [Errno 2] No such file or directory: '/home/alexluttrell2013/microblog/venv/lib/python3.8/site-packages/babel/locale-data'
2021-03-02 02:09:50,550 ERROR: Exception on /2018/wp-includes/wlwmanifest.xml [GET] [in /home/alexluttrell2013/microblog/venv/lib/python3.8/site-packages/flask/app.py:1891]
Traceback (most recent call last):
  File "/home/alexluttrell2013/microblog/venv/lib/python3.8/site-packages/flask/app.py", line 2447, in wsgi_app
  File "/home/alexluttrell2013/microblog/venv/lib/python3.8/site-packages/flask/app.py", line 1952, in full_dispatch_request
  File "/home/alexluttrell2013/microblog/venv/lib/python3.8/site-packages/flask/app.py", line 1821, in handle_user_exception
  File "/home/alexluttrell2013/microblog/venv/lib/python3.8/site-packages/flask/_compat.py", line 39, in reraise
  File "/home/alexluttrell2013/microblog/venv/lib/python3.8/site-packages/flask/app.py", line 1948, in full_dispatch_request
  File "/home/alexluttrell2013/microblog/venv/lib/python3.8/site-packages/flask/app.py", line 2242, in preprocess_request
  File "/home/alexluttrell2013/microblog/app/main/routes.py", line 21, in before_request
    g.locale = str(get_locale())
  File "/home/alexluttrell2013/microblog/venv/lib/python3.8/site-packages/flask_babel/__init__.py", line 230, in get_locale
  File "/home/alexluttrell2013/microblog/venv/lib/python3.8/site-packages/babel/core.py", line 288, in parse
  File "/home/alexluttrell2013/microblog/venv/lib/python3.8/site-packages/babel/core.py", line 273, in _try_load
  File "/home/alexluttrell2013/microblog/venv/lib/python3.8/site-packages/babel/core.py", line 167, in __init__
  File "/home/alexluttrell2013/microblog/venv/lib/python3.8/site-packages/babel/localedata.py", line 64, in exists
  File "/home/alexluttrell2013/microblog/venv/lib/python3.8/site-packages/babel/localedata.py", line 47, in normalize_locale
  File "/home/alexluttrell2013/microblog/venv/lib/python3.8/site-packages/babel/localedata.py", line 76, in locale_identifiers
FileNotFoundError: [Errno 2] No such file or directory: '/home/alexluttrell2013/microblog/venv/lib/python3.8/site-packages/babel/locale-data'
2021-03-02 02:09:50,755 ERROR: Exception on /2019/wp-includes/wlwmanifest.xml [GET] [in /home/alexluttrell2013/microblog/venv/lib/python3.8/site-packages/flask/app.py:1891]
Traceback (most recent call last):
  File "/home/alexluttrell2013/microblog/venv/lib/python3.8/site-packages/flask/app.py", line 2447, in wsgi_app
  File "/home/alexluttrell2013/microblog/venv/lib/python3.8/site-packages/flask/app.py", line 1952, in full_dispatch_request
  File "/home/alexluttrell2013/microblog/venv/lib/python3.8/site-packages/flask/app.py", line 1821, in handle_user_exception
  File "/home/alexluttrell2013/microblog/venv/lib/python3.8/site-packages/flask/_compat.py", line 39, in reraise
  File "/home/alexluttrell2013/microblog/venv/lib/python3.8/site-packages/flask/app.py", line 1948, in full_dispatch_request
  File "/home/alexluttrell2013/microblog/venv/lib/python3.8/site-packages/flask/app.py", line 2242, in preprocess_request
  File "/home/alexluttrell2013/microblog/app/main/routes.py", line 21, in before_request
    g.locale = str(get_locale())
  File "/home/alexluttrell2013/microblog/venv/lib/python3.8/site-packages/flask_babel/__init__.py", line 230, in get_locale
  File "/home/alexluttrell2013/microblog/venv/lib/python3.8/site-packages/babel/core.py", line 288, in parse
  File "/home/alexluttrell2013/microblog/venv/lib/python3.8/site-packages/babel/core.py", line 273, in _try_load
  File "/home/alexluttrell2013/microblog/venv/lib/python3.8/site-packages/babel/core.py", line 167, in __init__
  File "/home/alexluttrell2013/microblog/venv/lib/python3.8/site-packages/babel/localedata.py", line 64, in exists
  File "/home/alexluttrell2013/microblog/venv/lib/python3.8/site-packages/babel/localedata.py", line 47, in normalize_locale
  File "/home/alexluttrell2013/microblog/venv/lib/python3.8/site-packages/babel/localedata.py", line 76, in locale_identifiers
FileNotFoundError: [Errno 2] No such file or directory: '/home/alexluttrell2013/microblog/venv/lib/python3.8/site-packages/babel/locale-data'
